0906/output/july_2026_tolerant_as_gp_drift_results.json
{
  "as_of": "2026-09-06",
  "instrument": "HK 07709",
  "source_directory": "DEEPLOB_7709_DATA_DIR (local, not committed)",
  "design": {
    "data_family": "tolerant MBO reconstruction: ignore unknown modify/delete, quarantine five minutes after each >30s continuous-session gap, and split segments",
    "reconstruction_policy": "tolerant",
    "initial_period": "2026-07-02 first 70% model fit / last 30% calibration only",
    "full_day_out_of_sample_tests": [
      "2026-07-03",
      "2026-07-06",
      "2026-07-07",
      "2026-07-08",
      "2026-07-09",
      "2026-07-10",
      "2026-07-14",
      "2026-07-15",
      "2026-07-16",
      "2026-07-17",
      "2026-07-20",
      "2026-07-21",
      "2026-07-22",
      "2026-07-23",
      "2026-07-24",
      "2026-07-27",
      "2026-07-28",
      "2026-07-29",
      "2026-07-30"
    ],
    "direction_model": "class-balanced multinomial logistic regression on 25 causal LOB features",
    "direction_model_rolling_train_days": 5,
    "parameter_validation_rolling_periods": 5,
    "drift": "p(up)-p(down), linearly calibrated on prior OOS periods to expected 20-snapshot mid move in ticks",
    "strategies": {
      "classic_as": "finite-horizon AS closed-form quotes with prior-period variance and fill-decay estimates",
      "gp_style_discrete": "validation-tuned discrete tick/inventory approximation; not the original GP QVI solution",
      "directional": "GP-style discrete quote center plus calibrated directional drift",
      "paired_no_signal": "same directional parameters with signal strength forced to zero"
    },
    "execution": {
      "lot_size": 100,
      "latency_ms": 5,
      "quote_horizon_snapshots": 20,
      "through": "buy: bid quote >= future best ask/trade price + 1 tick; sell: ask quote <= future best bid/trade price - 1 tick; either evidence is sufficient",
      "touch": "buy: bid quote >= future best ask OR future trade price; sell: ask quote <= future best bid OR future trade price",
      "daily_terminal_flattening": true,
      "fill_evidence": "earliest qualifying future trade price OR opposite L1 best quote",
      "active_window": "snapshots t+1 through t+20 whose timestamp is later than t+5ms",
      "unfilled_at_horizon": "cancel after evaluating snapshot t+20"
    },
    "cost_bps_per_execution_side": {
      "official_fixed": 1.27,
      "brokerage_assumption": 1.5,
      "all_in": 2.77
    }
  },
  "source_audit": {
    "files_found": 25,
    "calendar_files": [
      {
        "date": "2026-07-02",
        "weekday": "Thursday",
        "bytes": 159575843
      },
      {
        "date": "2026-07-03",
        "weekday": "Friday",
        "bytes": 159456648
      },
      {
        "date": "2026-07-06",
        "weekday": "Monday",
        "bytes": 133059953
      },
      {
        "date": "2026-07-07",
        "weekday": "Tuesday",
        "bytes": 264650724
      },
      {
        "date": "2026-07-08",
        "weekday": "Wednesday",
        "bytes": 270745498
      },
      {
        "date": "2026-07-09",
        "weekday": "Thursday",
        "bytes": 294551133
      },
      {
        "date": "2026-07-10",
        "weekday": "Friday",
        "bytes": 173457403
      },
      {
        "date": "2026-07-12",
        "weekday": "Sunday",
        "bytes": 24915
      },
      {
        "date": "2026-07-13",
        "weekday": "Monday",
        "bytes": 267248993
      },
      {
        "date": "2026-07-14",
        "weekday": "Tuesday",
        "bytes": 271858196
      },
      {
        "date": "2026-07-15",
        "weekday": "Wednesday",
        "bytes": 187803297
      },
      {
        "date": "2026-07-16",
        "weekday": "Thursday",
        "bytes": 182069846
      },
      {
        "date": "2026-07-17",
        "weekday": "Friday",
        "bytes": 83422856
      },
      {
        "date": "2026-07-20",
        "weekday": "Monday",
        "bytes": 171231157
      },
      {
        "date": "2026-07-21",
        "weekday": "Tuesday",
        "bytes": 128067650
      },
      {
        "date": "2026-07-22",
        "weekday": "Wednesday",
        "bytes": 142239650
      },
      {
        "date": "2026-07-23",
        "weekday": "Thursday",
        "bytes": 133874233
      },
      {
        "date": "2026-07-24",
        "weekday": "Friday",
        "bytes": 120499790
      },
      {
        "date": "2026-07-25",
        "weekday": "Saturday",
        "bytes": 8891
      },
      {
        "date": "2026-07-26",
        "weekday": "Sunday",
        "bytes": 8612
      },
      {
        "date": "2026-07-27",
        "weekday": "Monday",
        "bytes": 113951334
      },
      {
        "date": "2026-07-28",
        "weekday": "Tuesday",
        "bytes": 155067468
      },
      {
        "date": "2026-07-29",
        "weekday": "Wednesday",
        "bytes": 239942828
      },
      {
        "date": "2026-07-30",
        "weekday": "Thursday",
        "bytes": 203516121
      },
      {
        "date": "2026-07-31",
        "weekday": "Friday",
        "bytes": 160930191
      }
    ],
    "reconstruction": [
      {
        "date": "2026-07-02",
        "status": "cached",
        "cache": "hk07709_2026-07-02_mbo_tolerant_5m_s10.npz",
        "snapshots": 108282,
        "tainted": false,
        "order_errors": {},
        "reconstruction_policy": "tolerant",
        "gap_events": [],
        "recovery_skipped_changed_groups": 0,
        "first_send_time": 20260702093001800,
        "last_send_time": 20260702155959628,
        "full_session_coverage": true
      },
      {
        "date": "2026-07-03",
        "status": "cached",
        "cache": "hk07709_2026-07-03_mbo_tolerant_5m_s10.npz",
        "snapshots": 98102,
        "tainted": false,
        "order_errors": {
          "delete_missing_order": 2723,
          "modify_missing_order": 134
        },
        "reconstruction_policy": "tolerant",
        "gap_events": [
          {
            "previous_send_time": 20260703093344404,
            "resume_send_time": 20260703093647406,
            "gap_ms": 183002,
            "recovery_until_day_ms": 34907406,
            "new_segment": 2
          }
        ],
        "recovery_skipped_changed_groups": 29436,
        "first_send_time": 20260703093000023,
        "last_send_time": 20260703155959352,
        "full_session_coverage": true
      },
      {
        "date": "2026-07-06",
        "status": "cached",
        "cache": "hk07709_2026-07-06_mbo_tolerant_5m_s10.npz",
        "snapshots": 87408,
        "tainted": false,
        "order_errors": {
          "delete_missing_order": 3734,
          "modify_missing_order": 515
        },
        "reconstruction_policy": "tolerant",
        "gap_events": [
          {
            "previous_send_time": 20260706093144352,
            "resume_send_time": 20260706093413642,
            "gap_ms": 149290,
            "recovery_until_day_ms": 34753642,
            "new_segment": 2
          },
          {
            "previous_send_time": 20260706101044355,
            "resume_send_time": 20260706101421747,
            "gap_ms": 217392,
            "recovery_until_day_ms": 37161747,
            "new_segment": 3
          }
        ],
        "recovery_skipped_changed_groups": 41119,
        "first_send_time": 20260706093000028,
        "last_send_time": 20260706155959396,
        "full_session_coverage": true
      },
      {
        "date": "2026-07-07",
        "status": "cached",
        "cache": "hk07709_2026-07-07_mbo_tolerant_5m_s10.npz",
        "snapshots": 152283,
        "tainted": false,
        "order_errors": {},
        "reconstruction_policy": "tolerant",
        "gap_events": [],
        "recovery_skipped_changed_groups": 0,
        "first_send_time": 20260707093000080,
        "last_send_time": 20260707155959716,
        "full_session_coverage": true
      },
      {
        "date": "2026-07-08",
        "status": "cached",
        "cache": "hk07709_2026-07-08_mbo_tolerant_5m_s10.npz",
